<?xml version="1.0"?>
<robot name="robovacuum" xmlns:xacro="http://ros.org/wiki/xacro">

  <!-- Include ros2_control Plugins -->
  <xacro:include filename="$(find robovacuum_description)/urdf/robovacuum_ros2_control.xacro" />

  <link name="base_link"/>
  <link name="wheel_left_link"/>
  <link name="wheel_right_link"/>

  <joint name="wheel_left_joint" type="continuous">
    <parent link="base_link"/>
    <child link="wheel_left_link"/>
    <origin xyz="0 0.2 0" rpy="0 0 0"/>
    <axis xyz="0 1 0"/>
  </joint>

  <joint name="wheel_right_joint" type="continuous">
    <parent link="base_link"/>
    <child link="wheel_right_link"/>
    <origin xyz="0 -0.2 0" rpy="0 0 0"/>
    <axis xyz="0 1 0"/>
  </joint>
</robot>
